<mujoco>
    <option collision="all" timestep="0.001" gravity="0 0 -9.81" cone="elliptic" />
    <compiler angle="radian" />

    <asset>
        <material class="panda" name="white"      rgba="1 1 1 1" />
        <material class="panda" name="off_white"  rgba="0.901961 0.921569 0.929412 1" />
        <material class="panda" name="black"      rgba="0.25 0.25 0.25 1" />
        <material class="panda" name="green"      rgba="0 1 0 1" />
        <material class="panda" name="light_blue" rgba="0.39216 0.541176 0.780392 1" />
        <material class="panda" name="red"        rgba="1 0 0 1" />
        <material class="panda" name="grey"       rgba="0.5 0.5 0.5 1" />

        <mesh name="link0_collision"  file="meshes/collision/link0.stl"  scale="1 1 1" />
        <mesh name="link1_collision"  file="meshes/collision/link1.stl"  scale="1 1 1" />
        <mesh name="link2_collision"  file="meshes/collision/link2.stl"  scale="1 1 1" />
        <mesh name="link3_collision"  file="meshes/collision/link3.stl"  scale="1 1 1" />
        <mesh name="link4_collision"  file="meshes/collision/link4.stl"  scale="1 1 1" />
        <mesh name="link5_0_collision"  file="meshes/collision/link5_collision_0.obj"  scale="1 1 1" />
        <mesh name="link5_1_collision"  file="meshes/collision/link5_collision_1.obj"  scale="1 1 1" />
        <mesh name="link5_2_collision"  file="meshes/collision/link5_collision_2.obj"  scale="1 1 1" />
        <mesh name="link6_collision"  file="meshes/collision/link6.stl"  scale="1 1 1" />
        <mesh name="link7_collision"  file="meshes/collision/link7.stl"  scale="1 1 1" />
        <mesh name="ubi_tip_collision"   file="meshes/collision/ubi_tip_collision.stl"   scale="0.001 0.001 0.001" />

        <mesh name="link0_0_visual"  file="meshes/visual/link0_0.obj"  scale="1 1 1" />
        <mesh name="link0_1_visual"  file="meshes/visual/link0_1.obj"  scale="1 1 1" />
        <mesh name="link0_2_visual"  file="meshes/visual/link0_2.obj"  scale="1 1 1" />
        <mesh name="link0_3_visual"  file="meshes/visual/link0_3.obj"  scale="1 1 1" />
        <mesh name="link0_4_visual"  file="meshes/visual/link0_4.obj"  scale="1 1 1" />
        <mesh name="link0_5_visual"  file="meshes/visual/link0_5.obj"  scale="1 1 1" />
        <mesh name="link0_7_visual"  file="meshes/visual/link0_7.obj"  scale="1 1 1" />
        <mesh name="link0_8_visual"  file="meshes/visual/link0_8.obj"  scale="1 1 1" />
        <mesh name="link0_9_visual"  file="meshes/visual/link0_9.obj"  scale="1 1 1" />
        <mesh name="link0_10_visual" file="meshes/visual/link0_10.obj"  scale="1 1 1" />
        <mesh name="link0_11_visual" file="meshes/visual/link0_11.obj"  scale="1 1 1" />
        <mesh name="link1_visual"  file="meshes/visual/link1.obj"  scale="1 1 1" />
        <mesh name="link2_visual"  file="meshes/visual/link2.obj"  scale="1 1 1" />
        <mesh name="link3_0_visual"  file="meshes/visual/link3_0.obj"  scale="1 1 1" />
        <mesh name="link3_1_visual"  file="meshes/visual/link3_1.obj"  scale="1 1 1" />
        <mesh name="link3_2_visual"  file="meshes/visual/link3_2.obj"  scale="1 1 1" />
        <mesh name="link3_3_visual"  file="meshes/visual/link3_3.obj"  scale="1 1 1" />
        <mesh name="link4_0_visual"  file="meshes/visual/link4_0.obj"  scale="1 1 1" />
        <mesh name="link4_1_visual"  file="meshes/visual/link4_1.obj"  scale="1 1 1" />
        <mesh name="link4_2_visual"  file="meshes/visual/link4_2.obj"  scale="1 1 1" />
        <mesh name="link4_3_visual"  file="meshes/visual/link4_3.obj"  scale="1 1 1" />
        <mesh name="link5_0_visual"  file="meshes/visual/link5_0.obj"  scale="1 1 1" />
        <mesh name="link5_1_visual"  file="meshes/visual/link5_1.obj"  scale="1 1 1" />
        <mesh name="link5_2_visual"  file="meshes/visual/link5_2.obj"  scale="1 1 1" />
        <mesh name="link6_0_visual"  file="meshes/visual/link6_0.obj"  scale="1 1 1" />
        <mesh name="link6_1_visual"  file="meshes/visual/link6_1.obj"  scale="1 1 1" />
        <mesh name="link6_2_visual"  file="meshes/visual/link6_2.obj"  scale="1 1 1" />
        <mesh name="link6_3_visual"  file="meshes/visual/link6_3.obj"  scale="1 1 1" />
        <mesh name="link6_4_visual"  file="meshes/visual/link6_4.obj"  scale="1 1 1" />
        <mesh name="link6_5_visual"  file="meshes/visual/link6_5.obj"  scale="1 1 1" />
        <mesh name="link6_6_visual"  file="meshes/visual/link6_6.obj"  scale="1 1 1" />
        <mesh name="link6_7_visual"  file="meshes/visual/link6_7.obj"  scale="1 1 1" />
        <mesh name="link6_8_visual"  file="meshes/visual/link6_8.obj"  scale="1 1 1" />
        <mesh name="link6_9_visual"  file="meshes/visual/link6_9.obj"  scale="1 1 1" />
        <mesh name="link6_10_visual"  file="meshes/visual/link6_10.obj"  scale="1 1 1" />
        <mesh name="link6_11_visual"  file="meshes/visual/link6_10.obj"  scale="1 1 1" />
        <mesh name="link6_12_visual"  file="meshes/visual/link6_12.obj"  scale="1 1 1" />
        <mesh name="link6_13_visual"  file="meshes/visual/link6_13.obj"  scale="1 1 1" />
        <mesh name="link6_14_visual"  file="meshes/visual/link6_14.obj"  scale="1 1 1" />
        <mesh name="link6_15_visual"  file="meshes/visual/link6_15.obj"  scale="1 1 1" />
        <mesh name="link6_16_visual"  file="meshes/visual/link6_16.obj"  scale="1 1 1" />
        <mesh name="link7_0_visual"  file="meshes/visual/link7_0.obj"  scale="1 1 1" />
        <mesh name="link7_1_visual"  file="meshes/visual/link7_1.obj"  scale="1 1 1" />
        <mesh name="link7_2_visual"  file="meshes/visual/link7_2.obj"  scale="1 1 1" />
        <mesh name="link7_3_visual"  file="meshes/visual/link7_3.obj"  scale="1 1 1" />
        <mesh name="link7_4_visual"  file="meshes/visual/link7_4.obj"  scale="1 1 1" />
        <mesh name="link7_5_visual"  file="meshes/visual/link7_5.obj"  scale="1 1 1" />
        <mesh name="link7_6_visual"  file="meshes/visual/link7_6.obj"  scale="1 1 1" />
        <mesh name="link7_7_visual"  file="meshes/visual/link7_7.obj"  scale="1 1 1" />
        <mesh name="poking_stick_for_ubi_visual" file="meshes/visual/poking_stick_for_ubi.stl" scale="0.001 0.001 0.001" />
        <mesh name="ubi_tip_visual" file="meshes/visual/ubi_tip_visual.stl" scale="0.001 0.001 0.001" />
    </asset>

    <default>
        <default class="panda">
            <material specular="0.5" shininess="0.25"/>
            <joint pos="0 0 0" axis="0 0 1" limited="true" damping="0.003" />

            <default class="visual">
                <geom type="mesh" contype="0" conaffinity="0" group="0" mass="0" />
            </default>
            <default class="collision">
                <geom contype="1" conaffinity="1" group="3" type="mesh" />
            </default>
        </default>
    </default>

    <worldbody>
        <light pos="0 0 1000" castshadow="false" />

        <body name="panda_link0" childclass="panda" pos="0 0 0" gravcomp="0">
            <inertial pos="-0.041018 -0.00014 0.049974" mass="0.629769" fullinertia="0.00315 0.00388 0.004285 8.2904E-07 0.00015 8.2299E-06" />
            <geom class="visual"    mesh="link0_0_visual"   material="off_white"/>
            <geom class="visual"    mesh="link0_1_visual"   material="black"/>
            <geom class="visual"    mesh="link0_2_visual"   material="off_white"/>
            <geom class="visual"    mesh="link0_3_visual"   material="black"/>
            <geom class="visual"    mesh="link0_4_visual"   material="off_white"/>
            <geom class="visual"    mesh="link0_5_visual"   material="black"/>
            <geom class="visual"    mesh="link0_7_visual"   material="white"/>
            <geom class="visual"    mesh="link0_8_visual"   material="white"/>
            <geom class="visual"    mesh="link0_9_visual"   material="black"/>
            <geom class="visual"    mesh="link0_10_visual"  material="off_white"/>
            <geom class="visual"    mesh="link0_11_visual"  material="white"/>
            <geom class="collision" mesh="link0_collision" />

            <body name="panda_link1" pos="0 0 0.333" gravcomp="0">
                <inertial pos="3.875e-03 2.081e-03 -4.762e-02" mass="4.970684" fullinertia="7.0337e-01 7.0661e-01 9.1170e-03 -1.3900e-04 6.7720e-03 1.9169e-02" />
                <joint name="panda_joint1" range="-2.8973 2.8973" />
                <geom class="visual"    mesh="link1_visual" material="white"/>
                <geom class="collision" mesh="link1_collision" />

                <body name="panda_link2" pos="0 0 0" quat="0.707107 -0.707107 0 0"  gravcomp="0">
                    <inertial pos="-3.141e-03 -2.872e-02  3.495e-03" mass="0.646926" fullinertia="7.9620e-03 2.8110e-02 2.5995e-02 -3.9250e-03 1.0254e-02 7.0400e-04" />
                    <joint name="panda_joint2" range="-1.7628 1.7628" />
                    <geom class="visual"    mesh="link2_visual" material="white"/>
                    <geom class="collision" mesh="link2_collision" />

                    <body name="panda_link3" pos="0 -0.316 0" quat="0.707107 0.707107 0 0" gravcomp="0">
                        <inertial pos="2.7518e-02 3.9252e-02 -6.6502e-02" mass="3.228604" fullinertia="3.7242e-02 3.6155e-02 1.0830e-02 -4.7610e-03 -1.1396e-02 -1.2805e-02" />
                        <joint name="panda_joint3" range="-2.8973 2.8973" />
                        <geom class="visual"    mesh="link3_0_visual"  material="white"/>
                        <geom class="visual"    mesh="link3_1_visual"  material="white"/>
                        <geom class="visual"    mesh="link3_2_visual"  material="white"/>
                        <geom class="visual"    mesh="link3_3_visual"  material="black"/>
                        <geom class="collision" mesh="link3_collision" />

                        <body name="panda_link4" pos="0.0825 0 0" quat="0.707107 0.707107 0 0" gravcomp="0">
                            <inertial pos="-5.317e-02 1.04419e-01 2.7454e-02" mass="3.587895" fullinertia="2.5853e-02 1.9552e-02 2.8323e-02 7.7960e-03 -1.3320e-03 8.6410e-03" />
                            <joint name="panda_joint4" range="-3.0718 -0.0698" />
                            <geom class="visual"    mesh="link4_0_visual"  material="white"/>
                            <geom class="visual"    mesh="link4_1_visual"  material="white"/>
                            <geom class="visual"    mesh="link4_2_visual"  material="black"/>
                            <geom class="visual"    mesh="link4_3_visual"  material="white"/>
                            <geom class="collision" mesh="link4_collision" />

                            <body name="panda_link5" pos="-0.0825 0.384 0" quat="0.707107 -0.707107 0 0" gravcomp="0">
                                <inertial pos="-1.1953e-02 4.1065e-02 -3.8437e-02" mass="1.225946" fullinertia="3.5549e-02 2.9474e-02 8.6270e-03 -2.1170e-03 -4.0370e-03 2.2900e-04" />
                                <joint name="panda_joint5" range="-2.8973 2.8973" />
                                <geom class="visual"    mesh="link5_0_visual"  material="black"/>
                                <geom class="visual"    mesh="link5_1_visual"  material="white"/>
                                <geom class="visual"    mesh="link5_2_visual"  material="white"/>
                                <geom class="collision" mesh="link5_0_collision" />
                                <geom class="collision" mesh="link5_1_collision" />
                                <geom class="collision" mesh="link5_2_collision" />

                                <body name="panda_link6" pos="0 0 0" quat="0.707107 0.707107 0 0" gravcomp="0">
                                    <inertial pos="6.0149e-02 -1.4117e-02 -1.0517e-02" mass="1.666555" fullinertia="1.9640e-03 4.3540e-03 5.4330e-03 1.0900e-04 -1.1580e-03 3.4100e-04" />
                                    <joint name="panda_joint6" range="-0.0175 3.7525" />
                                    <geom class="visual"    mesh="link6_0_visual"  material="off_white"/>
                                    <geom class="visual"    mesh="link6_1_visual"  material="white"/>
                                    <geom class="visual"    mesh="link6_2_visual"  material="black"/>
                                    <geom class="visual"    mesh="link6_3_visual"  material="white"/>
                                    <geom class="visual"    mesh="link6_4_visual"  material="white"/>
                                    <geom class="visual"    mesh="link6_5_visual"  material="white"/>
                                    <geom class="visual"    mesh="link6_6_visual"  material="white"/>
                                    <geom class="visual"    mesh="link6_7_visual"  material="light_blue"/>
                                    <geom class="visual"    mesh="link6_8_visual"  material="light_blue"/>
                                    <geom class="visual"    mesh="link6_9_visual"  material="black"/>
                                    <geom class="visual"    mesh="link6_10_visual" material="black"/>
                                    <geom class="visual"    mesh="link6_11_visual" material="white"/>
                                    <geom class="visual"    mesh="link6_12_visual" material="green"/>
                                    <geom class="visual"    mesh="link6_13_visual" material="white"/>
                                    <geom class="visual"    mesh="link6_14_visual" material="black"/>
                                    <geom class="visual"    mesh="link6_15_visual" material="black"/>
                                    <geom class="visual"    mesh="link6_16_visual" material="white"/>
                                    <geom class="collision" mesh="link6_collision" />

                                    <body name="panda_link7" pos="0.088 0 0" quat="0.707107 0.707107 0 0" gravcomp="0">
                                        <inertial pos="1.0517e-02 -4.252e-03 6.1597e-02" mass="7.35522e-01" fullinertia="1.2516e-02 1.0027e-02 4.8150e-03 -4.2800e-04 -1.1960e-03 -7.4100e-04" />
                                        <joint name="panda_joint7" range="-2.8973 2.8973" />
                                        <geom class="visual"    mesh="link7_0_visual"  material="white"/>
                                        <geom class="visual"    mesh="link7_1_visual"  material="black"/>
                                        <geom class="visual"    mesh="link7_2_visual"  material="black"/>
                                        <geom class="visual"    mesh="link7_3_visual"  material="black"/>
                                        <geom class="visual"    mesh="link7_4_visual"  material="black"/>
                                        <geom class="visual"    mesh="link7_5_visual"  material="black"/>
                                        <geom class="visual"    mesh="link7_6_visual"  material="black"/>
                                        <geom class="visual"    mesh="link7_7_visual"  material="white"/>
                                        <geom class="collision" mesh="link7_collision" />

                                        <body name="panda_poking_stick" pos="0 0 0.107" gravcomp="0">
                                            <inertial pos="0 0 0.0161" mass="0.505" diaginertia="0.000651 0.000651 0.000896"/>
                                            <geom name="panda_poking_stick_geom" class="visual" mesh="poking_stick_for_ubi_visual" material="black" pos="0 0 0" euler="0 0 0"/>
                                            <geom class="collision" type="cylinder" size="0.06725 0.0075" pos="0 0 0.0075"/>
                                            <geom class="collision" type="cylinder" size="0.05 0.005" pos="0 0 0.02"/>
                                            <geom class="collision" type="cylinder" size="0.025 0.005" pos="0 0 0.03"/>
                                            <geom class="collision" type="cylinder" size="0.0075 0.07225" pos="0 0 0.07375"/>

                                            <site name="panda_ee_site" pos="0 0 0.0161" rgba="0 0 0 0" size="0.02 0.02 0.02"></site>
                                            
                                            <body name="panda_ffdistal" pos="0 0 0.13605" gravcomp="0">
                                                <geom name="panda_fingertip_geom_visual" class="visual" mesh="ubi_tip_visual" pos="0 0 0" euler="0 0 0" material="white"/>
                                                <geom name="panda_fingertip_geom" class="collision" mesh="ubi_tip_collision" pos="0 0 0" euler="0 0 0"/>
                                                <site name="touch_site" type="ellipsoid" size="0.0107 0.008 0.0138"  pos="0 -0.00048 0.0185" euler="-0.17 0 0" rgba="0 1 0 0.2"/>
                                            </body>
                                        </body>
                                    </body>
                                </body>
                            </body>
                        </body>
                    </body>
                </body>
            </body>
        </body>
    </worldbody>
    <contact>
        <exclude body1="panda_link0" body2="panda_link1" />
        <exclude body1="panda_link0" body2="panda_link2" />
        <exclude body1="panda_link0" body2="panda_link3" />
        <exclude body1="panda_link0" body2="panda_link4" />

        <exclude body1="panda_link1" body2="panda_link2" />
        <exclude body1="panda_link1" body2="panda_link4" />

        <exclude body1="panda_link2" body2="panda_link3" />
        <exclude body1="panda_link2" body2="panda_link4" />

        <exclude body1="panda_link3" body2="panda_link4" />
        <exclude body1="panda_link3" body2="panda_link6" />

        <exclude body1="panda_link4" body2="panda_link5" />
        <exclude body1="panda_link4" body2="panda_link6" />
        <exclude body1="panda_link4" body2="panda_link7" />

        <exclude body1="panda_link5" body2="panda_link7" />

        <exclude body1="panda_link6" body2="panda_link7" />

        <exclude body1="panda_poking_stick" body2="panda_ffdistal" />
    </contact>

    <sensor>
        <touch name="tactile_sensor" site="touch_site"/>
    </sensor>
</mujoco>
